<?xml version="1.0"?>
<robot xmlns:xacro="http://www.ros.org/wiki/xacro">

    <!-- <xacro:include filename="colors.xacro"/> -->

    <joint name ="left_wheel_joint" type="continuous">
        <parent link="base_link"/>
        <child link="left_wheel"/>
        <origin xyz="0 0.175 0" rpy="-${pi/2} 0 0"/>
        <axis xyz="0 0 1"/>
    </joint>

    <link name="left_wheel">
        <visual>
            <geometry>
                <cylinder radius="0.05" length="0.04"/>
            </geometry>
        </visual>
        <material name="black"/>
    </link>

    <xacro:inertial_cylinder mass="0.1" length="0.04" radius="0.04">
        <origin xyz="0 0 0" rpy="0 0 0"/>
    </xacro:inertial_cylinder>


</robot>